Workbook

Sheet Inputs
B2: MULTIFAMILY BESS | OWNER ECONOMICS
B3: Draft V1 • Blue / pale blue = editable; black = formula; green = cross-sheet link. All amounts USD.
B5: BUILDING
B6: Building name | D6: text | E6: Enter project-specific data; no sample economics are embedded.
B7: Location | D7: city / state
B8: Residential units | D8: # | E8: Required only for per-unit resiliency.
B9: Utility | D9: text
B10: Rate / tariff | D10: text
B11: Analysis start date | C11: 46388 | D11: date | E11: Draft default. Use 1 January of a non-leap year; no DST adjustment.
B12: Annual electricity consumption | C12: =IF(C56=$C$72,SUM(Hourly_Operations!D6:D8765)*$C$69,"") | D12: kWh | E12: Calculated from the full baseline hourly profile.
B13: Peak building demand | C13: =IF(C56=$C$72,MAX(Hourly_Operations!D6:D8765),"") | D13: kW | E13: Hourly average; may differ from utility billing-interval demand.
B15: BATTERY — REFERENCE PERFORMANCE ASSUMPTIONS
B16: Rated battery power | D16: kW
B17: Nameplate energy capacity | D17: kWh
B18: Usable capacity | D18: % | E18: Reference only; not multiplied by SOC limits in this draft.
B19: Minimum state of charge | D19: %
B20: Maximum state of charge | D20: %
B21: Round-trip efficiency | D21: % | E21: Efficiency losses must already be represented in imported dispatch.
B22: Maximum cycles per day | D22: # / day
B23: Maximum cycles per year | D23: # / year
B24: Annual degradation | D24: % | E24: Reference only: physical savings remain constant in future years.
B25: Useful life | D25: years | E25: Reference only. Set the analysis period to a defensible operating horizon.
B26: Replacement year | C26: 0 | D26: year | E26: Draft default: 0 = none. Replacement outside the analysis horizon is omitted; dispatch is unchanged.
B27: Replacement cost | C27: 0 | D27: $ | E27: Draft default: 0. Fixed nominal cost in the selected year.
B28: Annual O&M | C28: 0 | D28: $ / year | E28: Draft default: 0; replace with expected owner cash expense.
B29: O&M escalation | C29: 0 | D29: % / year | E29: Draft default: 0%.
B31: INSTALLED CAPITAL COST
B32: Battery system | D32: $
B33: Power control system / PCS | D33: $
B34: Balance of system / electrical | D34: $
B35: Installation / construction | D35: $
B36: Engineering / permitting | D36: $
B37: Interconnection | D37: $
B38: Other upfront costs | D38: $ | E38: Enter zero explicitly for cost categories that do not apply.
B39: Total installed cost | C39: =IF(COUNT(C32:C38)=ROWS(C32:C38),SUM(C32:C38),"") | D39: $
B41: ANALYSIS ASSUMPTIONS
B42: Analysis period | D42: years | E42: Draft default: 25 years; supported 1–25. Red warns the horizon exceeds entered useful life.
B43: Discount rate | D43: % | E43: Illustrative draft default: 8%; not a researched project assumption.
B45: RESILIENCY — SELECT ONE ECONOMIC BENEFIT
B46: Resiliency method | C46: Flat annual | D46: dropdown | E46: Exactly one method is used; other method inputs are ignored.
...

Sheet Utility_Rates
B2: UTILITY RATES | MONTHLY INPUTS
B3: Enter 12 months of rates. Bills are reference-only. Select each month’s season, then edit the 24-hour TOU schedule below.
G4: $/kWh | H4: $/kWh | I4: $/kWh | J4: $/kWh
B5: Month | C5: Actual bill ($) | D5: Actual use (kWh) | E5: Actual peak (kW) | F5: Demand ($/kW-mo) | G5: Peak | H5: Shoulder | I5: Off-peak | J5: Super off-peak | K5: Season
B6: =IF(Inputs!$C$60,DATE(YEAR(Inputs!$C$11),ROW()-ROW($B$5),Inputs!$C$69),"") | K6: Winter
B7: =IF(Inputs!$C$60,DATE(YEAR(Inputs!$C$11),ROW()-ROW($B$5),Inputs!$C$69),"") | K7: Winter
B8: =IF(Inputs!$C$60,DATE(YEAR(Inputs!$C$11),ROW()-ROW($B$5),Inputs!$C$69),"") | K8: Winter
B9: =IF(Inputs!$C$60,DATE(YEAR(Inputs!$C$11),ROW()-ROW($B$5),Inputs!$C$69),"") | K9: Winter
B10: =IF(Inputs!$C$60,DATE(YEAR(Inputs!$C$11),ROW()-ROW($B$5),Inputs!$C$69),"") | K10: Winter
B11: =IF(Inputs!$C$60,DATE(YEAR(Inputs!$C$11),ROW()-ROW($B$5),Inputs!$C$69),"") | K11: Summer
B12: =IF(Inputs!$C$60,DATE(YEAR(Inputs!$C$11),ROW()-ROW($B$5),Inputs!$C$69),"") | K12: Summer
B13: =IF(Inputs!$C$60,DATE(YEAR(Inputs!$C$11),ROW()-ROW($B$5),Inputs!$C$69),"") | K13: Summer
B14: =IF(Inputs!$C$60,DATE(YEAR(Inputs!$C$11),ROW()-ROW($B$5),Inputs!$C$69),"") | K14: Summer
B15: =IF(Inputs!$C$60,DATE(YEAR(Inputs!$C$11),ROW()-ROW($B$5),Inputs!$C$69),"") | K15: Winter
B16: =IF(Inputs!$C$60,DATE(YEAR(Inputs!$C$11),ROW()-ROW($B$5),Inputs!$C$69),"") | K16: Winter
B17: =IF(Inputs!$C$60,DATE(YEAR(Inputs!$C$11),ROW()-ROW($B$5),Inputs!$C$69),"") | K17: Winter
B19: Annual actual electricity cost | C19: =IF(COUNT(C6:C17)=Inputs!$C$73,SUM(C6:C17),"")
B20: Actual bills entered | C20: =COUNT(C6:C17)
B22: Annual energy-rate escalation | C22: 0 | E22: Draft default: 0%; applied to Year 1 arbitrage savings.
B23: Annual demand-rate escalation | C23: 0 | E23: Draft default: 0%; applied to Year 1 demand savings.
B25: SIMPLE TOU SCHEDULE | PERIOD STARTING AT EACH HOUR
B26: Default: all hours Off-peak. Summer = Jun–Sep; Winter = other months. Both assumptions are editable; no holidays or DST.
B28: Hour starting | C28: Summer weekday | D28: Summer weekend | E28: Winter weekday | F28: Winter weekend
B29: =ROW()-ROW($B$29) | C29: Off-peak | D29: Off-peak | E29: Off-peak | F29: Off-peak
B30: =ROW()-ROW($B$29) | C30: Off-peak | D30: Off-peak | E30: Off-peak | F30: Off-peak
B31: =ROW()-ROW($B$29) | C31: Off-peak | D31: Off-peak | E31: Off-peak | F31: Off-peak
B32: =ROW()-ROW($B$29) | C32: Off-peak | D32: Off-peak | E32: Off-peak | F32: Off-peak
B33: =ROW()-ROW($B$29) | C33: Off-peak | D33: Off-peak | E33: Off-peak | F33: Off-peak
B34: =ROW()-ROW($B$29) | C34: Off-peak | D34: Off-peak | E34: Off-peak | F34: Off-peak
B35: =ROW()-ROW($B$29) | C35: Off-peak | D35: Off-peak | E35: Off-peak | F35: Off-peak
B36: =ROW()-ROW($B$29) | C36: Off-peak | D36: Off-peak | E36: Off-peak | F36: Off-peak
B37: =ROW()-ROW($B$29) | C37: Off-peak | D37: Off-peak | E37: Off-peak | F37: Off-peak
B38: =ROW()-ROW($B$29) | C38: Off-peak | D38: Off-peak | E38: Off-peak | F38: Off-peak
B39: =ROW()-ROW($B$29) | C39: Off-peak | D39: Off-peak | E39: Off-peak | F39: Off-peak
B40: =ROW()-ROW($B$29) | C40: Off-peak | D40: Off-peak | E40: Off-peak | F40: Off-peak
... B52: =ROW()-ROW($B$29) | C52: Off-peak | D52: Off-peak | E52: Off-peak | F52: Off-peak
B54: Choose Peak, Shoulder, Off-peak, or Super off-peak. Weekdays are Monday–Friday. Assign all 96 schedule cells.
B55: Bills may contain charges this simplified tariff omits. Actual consumption / peak are optional references, not cash-flow inputs.
B57: When filled by the SC 8 Battery Wizard: Demand ($/kW-mo) is the effective baseline rate (all demand charges over the 15-minute billing peak) and every TOU column holds the month's average all-in $/kWh, taxes included. They drive the readiness checks and the bill reconciliation; Value_Streams carries the exact savings.

Sheet Hourly_Operations
B2: HOURLY OPERATIONS | 8,760 ONE-HOUR INTERVALS
B3: Filled by the SC 8 Battery Wizard: D baseline and E dispatch are hourly averages of its 15-minute run (positive = discharge); H is the all-in energy rate for the hour, taxes included.
B4: {=Inputs!C65}
B5: Hour | C5: Date / time | D5: Baseline demand (kW) | E5: Battery dispatch (kW) | F5: Net grid demand (kW) | G5: TOU period | H5: Energy rate ($/kWh) | I5: Baseline cost ($/hour) | J5: Post-battery cost ($/hour)
B6: =ROW()-ROW($B$5) | C6: =IF(Inputs!$C$60,Inputs!$C$11+(B6-Inputs!$C$69)/Inputs!$C$70,"") | F6: =IF(COUNT(D6:E6)=COLUMNS(D6:E6),D6-E6,"") | G6: {=IF(AND(Inputs!$C$60,Inputs!$C$61),INDEX(Utility_Rates!$C$29:$F$52,HOUR(C6)+Inputs!$C$69,MATCH(INDEX(Utility_Rates!$K$6:$K$17,MONTH(C6))&IF(WEEKDAY(C6,Inputs!$C$76)<=Inputs!$C$74," weekday"," weekend"),Utility_Rates!$C$28:$F$28,Inputs!$C$68)),"")} | I6: =IF(AND(ISNUMBER(D6),ISNUMBER(H6)),D6*H6*Inputs!$C$69,"") | J6: =IF(AND(ISNUMBER(F6),ISNUMBER(H6),F6>=Inputs!$C$68),F6*H6*Inputs!$C$69,"")
B7: =ROW()-ROW($B$5) | C7: =IF(Inputs!$C$60,Inputs!$C$11+(B7-Inputs!$C$69)/Inputs!$C$70,"") | F7: =IF(COUNT(D7:E7)=COLUMNS(D7:E7),D7-E7,"") | G7: {=IF(AND(Inputs!$C$60,Inputs!$C$61),INDEX(Utility_Rates!$C$29:$F$52,HOUR(C7)+Inputs!$C$69,MATCH(INDEX(Utility_Rates!$K$6:$K$17,MONTH(C7))&IF(WEEKDAY(C7,Inputs!$C$76)<=Inputs!$C$74," weekday"," weekend"),Utility_Rates!$C$28:$F$28,Inputs!$C$68)),"")} | I7: =IF(AND(ISNUMBER(D7),ISNUMBER(H7)),D7*H7*Inputs!$C$69,"") | J7: =IF(AND(ISNUMBER(F7),ISNUMBER(H7),F7>=Inputs!$C$68),F7*H7*Inputs!$C$69,"")
B8: =ROW()-ROW($B$5) | C8: =IF(Inputs!$C$60,Inputs!$C$11+(B8-Inputs!$C$69)/Inputs!$C$70,"") | F8: =IF(COUNT(D8:E8)=COLUMNS(D8:E8),D8-E8,"") | G8: {=IF(AND(Inputs!$C$60,Inputs!$C$61),INDEX(Utility_Rates!$C$29:$F$52,HOUR(C8)+Inputs!$C$69,MATCH(INDEX(Utility_Rates!$K$6:$K$17,MONTH(C8))&IF(WEEKDAY(C8,Inputs!$C$76)<=Inputs!$C$74," weekday"," weekend"),Utility_Rates!$C$28:$F$28,Inputs!$C$68)),"")} | I8: =IF(AND(ISNUMBER(D8),ISNUMBER(H8)),D8*H8*Inputs!$C$69,"") | J8: =IF(AND(ISNUMBER(F8),ISNUMBER(H8),F8>=Inputs!$C$68),F8*H8*Inputs!$C$69,"")
B9: =ROW()-ROW($B$5) | C9: =IF(Inputs!$C$60,Inputs!$C$11+(B9-Inputs!$C$69)/Inputs!$C$70,"") | F9: =IF(COUNT(D9:E9)=COLUMNS(D9:E9),D9-E9,"") | G9: {=IF(AND(Inputs!$C$60,Inputs!$C$61),INDEX(Utility_Rates!$C$29:$F$52,HOUR(C9)+Inputs!$C$69,MATCH(INDEX(Utility_Rates!$K$6:$K$17,MONTH(C9))&IF(WEEKDAY(C9,Inputs!$C$76)<=Inputs!$C$74," weekday"," weekend"),Utility_Rates!$C$28:$F$28,Inputs!$C$68)),"")} | I9: =IF(AND(ISNUMBER(D9),ISNUMBER(H9)),D9*H9*Inputs!$C$69,"") | J9: =IF(AND(ISNUMBER(F9),ISNUMBER(H9),F9>=Inputs!$C$68),F9*H9*Inputs!$C$69,"")
B10: =ROW()-ROW($B$5) | C10: =IF(Inputs!$C$60,Inputs!$C$11+(B10-Inputs!$C$69)/Inputs!$C$70,"") | F10: =IF(COUNT(D10:E10)=COLUMNS(D10:E10),D10-E10,"") | G10: {=IF(AND(Inputs!$C$60,Inputs!$C$61),INDEX(Utility_Rates!$C$29:$F$52,HOUR(C10)+Inputs!$C$69,MATCH(INDEX(Utility_Rates!$K$6:$K$17,MONTH(C10))&IF(WEEKDAY(C10,Inputs!$C$76)<=Inputs!$C$74," weekday"," weekend"),Utility_Rates!$C$28:$F$28,Inputs!$C$68)),"")} | I10: =IF(AND(ISNUMBER(D10),ISNUMBER(H10)),D10*H10*Inputs!$C$69,"") | J10: =IF(AND(ISNUMBER(F10),ISNUMBER(H10),F10>=Inputs!$C$68),F10*H10*Inputs!$C$69,"")
B11: =ROW()-ROW($B$5) | C11: =IF(Inputs!$C$60,Inputs!$C$11+(B11-Inputs!$C$69)/Inputs!$C$70,"") | F11: =IF(COUNT(D11:E11)=COLUMNS(D11:E11),D11-E11,"") | G11: {=IF(AND(Inputs!$C$60,Inputs!$C$61),INDEX(Utility_Rates!$C$29:$F$52,HOUR(C11)+Inputs!$C$69,MATCH(INDEX(Utility_Rates!$K$6:$K$17,MONTH(C11))&IF(WEEKDAY(C11,Inputs!$C$76)<=Inputs!$C$74," weekday"," weekend"),Utility_Rates!$C$28:$F$28,Inputs!$C$68)),"")} | I11: =IF(AND(ISNUMBER(D11),ISNUMBER(H11)),D11*H11*Inputs!$C$69,"") | J11: =IF(AND(ISNUMBER(F11),ISNUMBER(H11),F11>=Inputs!$C$68),F11*H11*Inputs!$C$69,"")
B12: =ROW()-ROW($B$5) | C12: =IF(Inputs!$C$60,Inputs!$C$11+(B12-Inputs!$C$69)/Inputs!$C$70,"") | F12: =IF(COUNT(D12:E12)=COLUMNS(D12:E12),D12-E12,"") | G12: {=IF(AND(Inputs!$C$60,Inputs!$C$61),INDEX(Utility_Rates!$C$29:$F$52,HOUR(C12)+Inputs!$C$69,MATCH(INDEX(Utility_Rates!$K$6:$K$17,MONTH(C12))&IF(WEEKDAY(C12,Inputs!$C$76)<=Inputs!$C$74," weekday"," weekend"),Utility_Rates!$C$28:$F$28,Inputs!$C$68)),"")} | I12: =IF(AND(ISNUMBER(D12),ISNUMBER(H12)),D12*H12*Inputs!$C$69,"") | J12: =IF(AND(ISNUMBER(F12),ISNUMBER(H12),F12>=Inputs!$C$68),F12*H12*Inputs!$C$69,"")
B13: =ROW()-ROW($B$5) | C13: =IF(Inputs!$C$60,Inputs!$C$11+(B13-Inputs!$C$69)/Inputs!$C$70,"") | F13: =IF(COUNT(D13:E13)=COLUMNS(D13:E13),D13-E13,"") | G13: {=IF(AND(Inputs!$C$60,Inputs!$C$61),INDEX(Utility_Rates!$C$29:$F$52,HOUR(C13)+Inputs!$C$69,MATCH(INDEX(Utility_Rates!$K$6:$K$17,MONTH(C13))&IF(WEEKDAY(C13,Inputs!$C$76)<=Inputs!$C$74," weekday"," weekend"),Utility_Rates!$C$28:$F$28,Inputs!$C$68)),"")} | I13: =IF(AND(ISNUMBER(D13),ISNUMBER(H13)),D13*H13*Inputs!$C$69,"") | J13: =IF(AND(ISNUMBER(F13),ISNUMBER(H13),F13>=Inputs!$C$68),F13*H13*Inputs!$C$69,"")
B14: =ROW()-ROW($B$5) | C14: =IF(Inputs!$C$60,Inputs!$C$11+(B14-Inputs!$C$69)/Inputs!$C$70,"") | F14: =IF(COUNT(D14:E14)=COLUMNS(D14:E14),D14-E14,"") | G14: {=IF(AND(Inputs!$C$60,Inputs!$C$61),INDEX(Utility_Rates!$C$29:$F$52,HOUR(C14)+Inputs!$C$69,MATCH(INDEX(Utility_Rates!$K$6:$K$17,MONTH(C14))&IF(WEEKDAY(C14,Inputs!$C$76)<=Inputs!$C$74," weekday"," weekend"),Utility_Rates!$C$28:$F$28,Inputs!$C$68)),"")} | I14: =IF(AND(ISNUMBER(D14),ISNUMBER(H14)),D14*H14*Inputs!$C$69,"") | J14: =IF(AND(ISNUMBER(F14),ISNUMBER(H14),F14>=Inputs!$C$68),F14*H14*Inputs!$C$69,"")
B15: =ROW()-ROW($B$5) | C15: =IF(Inputs!$C$60,Inputs!$C$11+(B15-Inputs!$C$69)/Inputs!$C$70,"") | F15: =IF(COUNT(D15:E15)=COLUMNS(D15:E15),D15-E15,"") | G15: {=IF(AND(Inputs!$C$60,Inputs!$C$61),INDEX(Utility_Rates!$C$29:$F$52,HOUR(C15)+Inputs!$C$69,MATCH(INDEX(Utility_Rates!$K$6:$K$17,MONTH(C15))&IF(WEEKDAY(C15,Inputs!$C$76)<=Inputs!$C$74," weekday"," weekend"),Utility_Rates!$C$28:$F$28,Inputs!$C$68)),"")} | I15: =IF(AND(ISNUMBER(D15),ISNUMBER(H15)),D15*H15*Inputs!$C$69,"") | J15: =IF(AND(ISNUMBER(F15),ISNUMBER(H15),F15>=Inputs!$C$68),F15*H15*Inputs!$C$69,"")
B16: =ROW()-ROW($B$5) | C16: =IF(Inputs!$C$60,Inputs!$C$11+(B16-Inputs!$C$69)/Inputs!$C$70,"") | F16: =IF(COUNT(D16:E16)=COLUMNS(D16:E16),D16-E16,"") | G16: {=IF(AND(Inputs!$C$60,Inputs!$C$61),INDEX(Utility_Rates!$C$29:$F$52,HOUR(C16)+Inputs!$C$69,MATCH(INDEX(Utility_Rates!$K$6:$K$17,MONTH(C16))&IF(WEEKDAY(C16,Inputs!$C$76)<=Inputs!$C$74," weekday"," weekend"),Utility_Rates!$C$28:$F$28,Inputs!$C$68)),"")} | I16: =IF(AND(ISNUMBER(D16),ISNUMBER(H16)),D16*H16*Inputs!$C$69,"") | J16: =IF(AND(ISNUMBER(F16),ISNUMBER(H16),F16>=Inputs!$C$68),F16*H16*Inputs!$C$69,"")
B17: =ROW()-ROW($B$5) | C17: =IF(Inputs!$C$60,Inputs!$C$11+(B17-Inputs!$C$69)/Inputs!$C$70,"") | F17: =IF(COUNT(D17:E17)=COLUMNS(D17:E17),D17-E17,"") | G17: {=IF(AND(Inputs!$C$60,Inputs!$C$61),INDEX(Utility_Rates!$C$29:$F$52,HOUR(C17)+Inputs!$C$69,MATCH(INDEX(Utility_Rates!$K$6:$K$17,MONTH(C17))&IF(WEEKDAY(C17,Inputs!$C$76)<=Inputs!$C$74," weekday"," weekend"),Utility_Rates!$C$28:$F$28,Inputs!$C$68)),"")} | I17: =IF(AND(ISNUMBER(D17),ISNUMBER(H17)),D17*H17*Inputs!$C$69,"") | J17: =IF(AND(ISNUMBER(F17),ISNUMBER(H17),F17>=Inputs!$C$68),F17*H17*Inputs!$C$69,"")
... B8765: =ROW()-ROW($B$5) | C8765: =IF(Inputs!$C$60,Inputs!$C$11+(B8765-Inputs!$C$69)/Inputs!$C$70,"") | F8765: =IF(COUNT(D8765:E8765)=COLUMNS(D8765:E8765),D8765-E8765,"") | G8765: {=IF(AND(Inputs!$C$60,Inputs!$C$61),INDEX(Utility_Rates!$C$29:$F$52,HOUR(C8765)+Inputs!$C$69,MATCH(INDEX(Utility_Rates!$K$6:$K$17,MONTH(C8765))&IF(WEEKDAY(C8765,Inputs!$C$76)<=Inputs!$C$74," weekday"," weekend"),Utility_Rates!$C$28:$F$28,Inputs!$C$68)),"")} | I8765: =IF(AND(ISNUMBER(D8765),ISNUMBER(H8765)),D8765*H8765*Inputs!$C$69,"") | J8765: =IF(AND(ISNUMBER(F8765),ISNUMBER(H8765),F8765>=Inputs!$C$68),F8765*H8765*Inputs!$C$69,"")

Sheet Value_Streams
B2: VALUE STREAMS | YEAR 1
B3: Savings appear once both profiles and monthly tariffs are complete and no exports are present. Negative savings are retained.
B5: Month | C5: Baseline peak (kW) | D5: Post-battery peak (kW) | E5: Peak reduction (kW) | F5: Demand ($/kW-mo) | G5: Demand savings ($) | H5: Baseline energy ($) | I5: Post-battery energy ($) | J5: Arbitrage savings ($) | K5: Program revenue ($) | L5: Resiliency value ($) | M5: Total benefit ($)
B6: {=Utility_Rates!B6} | E6: =IF(Inputs!$C$62,C6-D6,"") | F6: {=IF(ISNUMBER(Utility_Rates!F6),Utility_Rates!F6,"")} | H6: =IF(Inputs!$C$62,SUMIFS(Hourly_Operations!$I$6:$I$8765,Hourly_Operations!$C$6:$C$8765,">="&$B6,Hourly_Operations!$C$6:$C$8765,"<"&EDATE($B6,Inputs!$C$69)),"") | I6: =IF(Inputs!$C$62,SUMIFS(Hourly_Operations!$J$6:$J$8765,Hourly_Operations!$C$6:$C$8765,">="&$B6,Hourly_Operations!$C$6:$C$8765,"<"&EDATE($B6,Inputs!$C$69)),"") | J6: =IF(Inputs!$C$62,H6-I6,"") | L6: =IF(ISNUMBER(Inputs!$C$53),Inputs!$C$53/Inputs!$C$73,"") | M6: =IF(AND(Inputs!$C$62,ISNUMBER(L6)),SUM(G6,J6,K6,L6),"")
B7: {=Utility_Rates!B7} | E7: =IF(Inputs!$C$62,C7-D7,"") | F7: {=IF(ISNUMBER(Utility_Rates!F7),Utility_Rates!F7,"")} | H7: =IF(Inputs!$C$62,SUMIFS(Hourly_Operations!$I$6:$I$8765,Hourly_Operations!$C$6:$C$8765,">="&$B7,Hourly_Operations!$C$6:$C$8765,"<"&EDATE($B7,Inputs!$C$69)),"") | I7: =IF(Inputs!$C$62,SUMIFS(Hourly_Operations!$J$6:$J$8765,Hourly_Operations!$C$6:$C$8765,">="&$B7,Hourly_Operations!$C$6:$C$8765,"<"&EDATE($B7,Inputs!$C$69)),"") | J7: =IF(Inputs!$C$62,H7-I7,"") | L7: =IF(ISNUMBER(Inputs!$C$53),Inputs!$C$53/Inputs!$C$73,"") | M7: =IF(AND(Inputs!$C$62,ISNUMBER(L7)),SUM(G7,J7,K7,L7),"")
B8: {=Utility_Rates!B8} | E8: =IF(Inputs!$C$62,C8-D8,"") | F8: {=IF(ISNUMBER(Utility_Rates!F8),Utility_Rates!F8,"")} | H8: =IF(Inputs!$C$62,SUMIFS(Hourly_Operations!$I$6:$I$8765,Hourly_Operations!$C$6:$C$8765,">="&$B8,Hourly_Operations!$C$6:$C$8765,"<"&EDATE($B8,Inputs!$C$69)),"") | I8: =IF(Inputs!$C$62,SUMIFS(Hourly_Operations!$J$6:$J$8765,Hourly_Operations!$C$6:$C$8765,">="&$B8,Hourly_Operations!$C$6:$C$8765,"<"&EDATE($B8,Inputs!$C$69)),"") | J8: =IF(Inputs!$C$62,H8-I8,"") | L8: =IF(ISNUMBER(Inputs!$C$53),Inputs!$C$53/Inputs!$C$73,"") | M8: =IF(AND(Inputs!$C$62,ISNUMBER(L8)),SUM(G8,J8,K8,L8),"")
B9: {=Utility_Rates!B9} | E9: =IF(Inputs!$C$62,C9-D9,"") | F9: {=IF(ISNUMBER(Utility_Rates!F9),Utility_Rates!F9,"")} | H9: =IF(Inputs!$C$62,SUMIFS(Hourly_Operations!$I$6:$I$8765,Hourly_Operations!$C$6:$C$8765,">="&$B9,Hourly_Operations!$C$6:$C$8765,"<"&EDATE($B9,Inputs!$C$69)),"") | I9: =IF(Inputs!$C$62,SUMIFS(Hourly_Operations!$J$6:$J$8765,Hourly_Operations!$C$6:$C$8765,">="&$B9,Hourly_Operations!$C$6:$C$8765,"<"&EDATE($B9,Inputs!$C$69)),"") | J9: =IF(Inputs!$C$62,H9-I9,"") | L9: =IF(ISNUMBER(Inputs!$C$53),Inputs!$C$53/Inputs!$C$73,"") | M9: =IF(AND(Inputs!$C$62,ISNUMBER(L9)),SUM(G9,J9,K9,L9),"")
B10: {=Utility_Rates!B10} | E10: =IF(Inputs!$C$62,C10-D10,"") | F10: {=IF(ISNUMBER(Utility_Rates!F10),Utility_Rates!F10,"")} | H10: =IF(Inputs!$C$62,SUMIFS(Hourly_Operations!$I$6:$I$8765,Hourly_Operations!$C$6:$C$8765,">="&$B10,Hourly_Operations!$C$6:$C$8765,"<"&EDATE($B10,Inputs!$C$69)),"") | I10: =IF(Inputs!$C$62,SUMIFS(Hourly_Operations!$J$6:$J$8765,Hourly_Operations!$C$6:$C$8765,">="&$B10,Hourly_Operations!$C$6:$C$8765,"<"&EDATE($B10,Inputs!$C$69)),"") | J10: =IF(Inputs!$C$62,H10-I10,"") | L10: =IF(ISNUMBER(Inputs!$C$53),Inputs!$C$53/Inputs!$C$73,"") | M10: =IF(AND(Inputs!$C$62,ISNUMBER(L10)),SUM(G10,J10,K10,L10),"")
B11: {=Utility_Rates!B11} | E11: =IF(Inputs!$C$62,C11-D11,"") | F11: {=IF(ISNUMBER(Utility_Rates!F11),Utility_Rates!F11,"")} | H11: =IF(Inputs!$C$62,SUMIFS(Hourly_Operations!$I$6:$I$8765,Hourly_Operations!$C$6:$C$8765,">="&$B11,Hourly_Operations!$C$6:$C$8765,"<"&EDATE($B11,Inputs!$C$69)),"") | I11: =IF(Inputs!$C$62,SUMIFS(Hourly_Operations!$J$6:$J$8765,Hourly_Operations!$C$6:$C$8765,">="&$B11,Hourly_Operations!$C$6:$C$8765,"<"&EDATE($B11,Inputs!$C$69)),"") | J11: =IF(Inputs!$C$62,H11-I11,"") | L11: =IF(ISNUMBER(Inputs!$C$53),Inputs!$C$53/Inputs!$C$73,"") | M11: =IF(AND(Inputs!$C$62,ISNUMBER(L11)),SUM(G11,J11,K11,L11),"")
B12: {=Utility_Rates!B12} | E12: =IF(Inputs!$C$62,C12-D12,"") | F12: {=IF(ISNUMBER(Utility_Rates!F12),Utility_Rates!F12,"")} | H12: =IF(Inputs!$C$62,SUMIFS(Hourly_Operations!$I$6:$I$8765,Hourly_Operations!$C$6:$C$8765,">="&$B12,Hourly_Operations!$C$6:$C$8765,"<"&EDATE($B12,Inputs!$C$69)),"") | I12: =IF(Inputs!$C$62,SUMIFS(Hourly_Operations!$J$6:$J$8765,Hourly_Operations!$C$6:$C$8765,">="&$B12,Hourly_Operations!$C$6:$C$8765,"<"&EDATE($B12,Inputs!$C$69)),"") | J12: =IF(Inputs!$C$62,H12-I12,"") | L12: =IF(ISNUMBER(Inputs!$C$53),Inputs!$C$53/Inputs!$C$73,"") | M12: =IF(AND(Inputs!$C$62,ISNUMBER(L12)),SUM(G12,J12,K12,L12),"")
B13: {=Utility_Rates!B13} | E13: =IF(Inputs!$C$62,C13-D13,"") | F13: {=IF(ISNUMBER(Utility_Rates!F13),Utility_Rates!F13,"")} | H13: =IF(Inputs!$C$62,SUMIFS(Hourly_Operations!$I$6:$I$8765,Hourly_Operations!$C$6:$C$8765,">="&$B13,Hourly_Operations!$C$6:$C$8765,"<"&EDATE($B13,Inputs!$C$69)),"") | I13: =IF(Inputs!$C$62,SUMIFS(Hourly_Operations!$J$6:$J$8765,Hourly_Operations!$C$6:$C$8765,">="&$B13,Hourly_Operations!$C$6:$C$8765,"<"&EDATE($B13,Inputs!$C$69)),"") | J13: =IF(Inputs!$C$62,H13-I13,"") | L13: =IF(ISNUMBER(Inputs!$C$53),Inputs!$C$53/Inputs!$C$73,"") | M13: =IF(AND(Inputs!$C$62,ISNUMBER(L13)),SUM(G13,J13,K13,L13),"")
B14: {=Utility_Rates!B14} | E14: =IF(Inputs!$C$62,C14-D14,"") | F14: {=IF(ISNUMBER(Utility_Rates!F14),Utility_Rates!F14,"")} | H14: =IF(Inputs!$C$62,SUMIFS(Hourly_Operations!$I$6:$I$8765,Hourly_Operations!$C$6:$C$8765,">="&$B14,Hourly_Operations!$C$6:$C$8765,"<"&EDATE($B14,Inputs!$C$69)),"") | I14: =IF(Inputs!$C$62,SUMIFS(Hourly_Operations!$J$6:$J$8765,Hourly_Operations!$C$6:$C$8765,">="&$B14,Hourly_Operations!$C$6:$C$8765,"<"&EDATE($B14,Inputs!$C$69)),"") | J14: =IF(Inputs!$C$62,H14-I14,"") | L14: =IF(ISNUMBER(Inputs!$C$53),Inputs!$C$53/Inputs!$C$73,"") | M14: =IF(AND(Inputs!$C$62,ISNUMBER(L14)),SUM(G14,J14,K14,L14),"")
B15: {=Utility_Rates!B15} | E15: =IF(Inputs!$C$62,C15-D15,"") | F15: {=IF(ISNUMBER(Utility_Rates!F15),Utility_Rates!F15,"")} | H15: =IF(Inputs!$C$62,SUMIFS(Hourly_Operations!$I$6:$I$8765,Hourly_Operations!$C$6:$C$8765,">="&$B15,Hourly_Operations!$C$6:$C$8765,"<"&EDATE($B15,Inputs!$C$69)),"") | I15: =IF(Inputs!$C$62,SUMIFS(Hourly_Operations!$J$6:$J$8765,Hourly_Operations!$C$6:$C$8765,">="&$B15,Hourly_Operations!$C$6:$C$8765,"<"&EDATE($B15,Inputs!$C$69)),"") | J15: =IF(Inputs!$C$62,H15-I15,"") | L15: =IF(ISNUMBER(Inputs!$C$53),Inputs!$C$53/Inputs!$C$73,"") | M15: =IF(AND(Inputs!$C$62,ISNUMBER(L15)),SUM(G15,J15,K15,L15),"")
B16: {=Utility_Rates!B16} | E16: =IF(Inputs!$C$62,C16-D16,"") | F16: {=IF(ISNUMBER(Utility_Rates!F16),Utility_Rates!F16,"")} | H16: =IF(Inputs!$C$62,SUMIFS(Hourly_Operations!$I$6:$I$8765,Hourly_Operations!$C$6:$C$8765,">="&$B16,Hourly_Operations!$C$6:$C$8765,"<"&EDATE($B16,Inputs!$C$69)),"") | I16: =IF(Inputs!$C$62,SUMIFS(Hourly_Operations!$J$6:$J$8765,Hourly_Operations!$C$6:$C$8765,">="&$B16,Hourly_Operations!$C$6:$C$8765,"<"&EDATE($B16,Inputs!$C$69)),"") | J16: =IF(Inputs!$C$62,H16-I16,"") | L16: =IF(ISNUMBER(Inputs!$C$53),Inputs!$C$53/Inputs!$C$73,"") | M16: =IF(AND(Inputs!$C$62,ISNUMBER(L16)),SUM(G16,J16,K16,L16),"")
B17: {=Utility_Rates!B17} | E17: =IF(Inputs!$C$62,C17-D17,"") | F17: {=IF(ISNUMBER(Utility_Rates!F17),Utility_Rates!F17,"")} | H17: =IF(Inputs!$C$62,SUMIFS(Hourly_Operations!$I$6:$I$8765,Hourly_Operations!$C$6:$C$8765,">="&$B17,Hourly_Operations!$C$6:$C$8765,"<"&EDATE($B17,Inputs!$C$69)),"") | I17: =IF(Inputs!$C$62,SUMIFS(Hourly_Operations!$J$6:$J$8765,Hourly_Operations!$C$6:$C$8765,">="&$B17,Hourly_Operations!$C$6:$C$8765,"<"&EDATE($B17,Inputs!$C$69)),"") | J17: =IF(Inputs!$C$62,H17-I17,"") | L17: =IF(ISNUMBER(Inputs!$C$53),Inputs!$C$53/Inputs!$C$73,"") | M17: =IF(AND(Inputs!$C$62,ISNUMBER(L17)),SUM(G17,J17,K17,L17),"")
B18: YEAR 1 TOTAL | G18: =IF(Inputs!$C$62,SUM(G6:G17),"") | H18: =IF(Inputs!$C$62,SUM(H6:H17),"") | I18: =IF(Inputs!$C$62,SUM(I6:I17),"") | J18: =IF(Inputs!$C$62,SUM(J6:J17),"") | K18: =SUM(K6:K17) | L18: {=IF(ISNUMBER(Inputs!$C$53),Inputs!$C$53,"")} | M18: =IF(AND(Inputs!$C$62,ISNUMBER(L18)),SUM(G18,J18,K18,L18),"")
B21: BILL RECONCILIATION | REFERENCE ONLY
B22: Annual actual electricity bills | C22: {=IF(ISNUMBER(Utility_Rates!C19),Utility_Rates!C19,"")}
B23: Modeled baseline bill | C23: =IF(Inputs!$C$62,H18+SUMPRODUCT(C6:C17,F6:F17),"")
B24: Modeled post-battery bill | C24: =IF(Inputs!$C$62,I18+SUMPRODUCT(D6:D17,F6:F17),"")
B25: Actual less modeled baseline | C25: =IF(AND(ISNUMBER(C22),ISNUMBER(C23)),C22-C23,"")
B28: Hourly peaks approximate shorter billing intervals; no ratchets or multiple demand windows are modeled.
B29: Arbitrage already includes charging purchases and imported losses. Do not deduct charging costs a second time.
B30: Resiliency is allocated evenly across months for display only; it is an assumed benefit, not necessarily cash received.
B31: Actual bills are never deducted again in project cash flow. Reconciliation gaps may include fixed or unmodeled tariff charges.
B32: Blue cells are filled by the SC 8 Battery Wizard: 15-minute billing peaks (C:D) and demand savings (G) cover every demand window, the SBC demand surcharge and the supply capacity charge, taxes included, so G is not simply E x F.
B33: Program revenue (K): Rider T CSRP / DLRP and Rider AC Term-DLM, from the same dispatch. Reservation payments are spread over the Capability Period months, performance payments land in the event months.

Sheet Project_Cash_Flow
B2: PROJECT CASH FLOW | SINGLE OWNER • UNLEVERED
B3: USD • Year 0 investment; annual benefits / expenses at year-end. No debt, tax, incentives, or terminal value.
B5: Year | C5: Installed cost | D5: Demand savings | E5: Arbitrage savings | F5: Program revenue | G5: Resiliency value | H5: Total economic benefit | I5: O&M expense | J5: Replacement cost | K5: Net excl. resiliency | L5: Cumulative excl. | M5: Net incl. resiliency | N5: Cumulative incl.
B6: =IF(ROW()-ROW($B$6)<=Inputs!$C$42,ROW()-ROW($B$6),"") | C6: =IF(AND(Inputs!$C$64,ISNUMBER($B6)),IF($B6=Inputs!$C$68,-Inputs!$C$39,Inputs!$C$68),"") | D6: {=IF(AND(Inputs!$C$64,ISNUMBER($B6)),IF($B6=Inputs!$C$68,Inputs!$C$68,Value_Streams!$G$18*(Inputs!$C$69+Utility_Rates!$C$23)^($B6-Inputs!$C$69)),"")} | E6: {=IF(AND(Inputs!$C$64,ISNUMBER($B6)),IF($B6=Inputs!$C$68,Inputs!$C$68,Value_Streams!$J$18*(Inputs!$C$69+Utility_Rates!$C$22)^($B6-Inputs!$C$69)),"")} | F6: =IF(AND(Inputs!$C$64,ISNUMBER($B6)),IF($B6=Inputs!$C$68,Inputs!$C$68,Value_Streams!$K$18),"") | G6: {=IF(AND(Inputs!$C$64,ISNUMBER($B6)),IF($B6=Inputs!$C$68,Inputs!$C$68,Inputs!$C$53),"")} | H6: =IF(AND(Inputs!$C$64,ISNUMBER($B6)),SUM(D6:G6),"") | I6: {=IF(AND(Inputs!$C$64,ISNUMBER($B6)),IF($B6=Inputs!$C$68,Inputs!$C$68,-Inputs!$C$28*(Inputs!$C$69+Inputs!$C$29)^($B6-Inputs!$C$69)),"")} | J6: {=IF(AND(Inputs!$C$64,ISNUMBER($B6)),IF(AND($B6>=Inputs!$C$69,$B6=Inputs!$C$26),-Inputs!$C$27,Inputs!$C$68),"")} | K6: =IF(AND(Inputs!$C$64,ISNUMBER($B6)),SUM(C6:F6,I6:J6),"") | L6: =IF(AND(Inputs!$C$64,ISNUMBER($B6)),SUM(K$6:K6),"") | M6: =IF(AND(Inputs!$C$64,ISNUMBER($B6)),K6+G6,"") | N6: =IF(AND(Inputs!$C$64,ISNUMBER($B6)),SUM(M$6:M6),"")
B7: =IF(ROW()-ROW($B$6)<=Inputs!$C$42,ROW()-ROW($B$6),"") | C7: {=IF(AND(Inputs!$C$64,ISNUMBER($B7)),IF($B7=Inputs!$C$68,-Inputs!$C$39,Inputs!$C$68),"")} | D7: =IF(AND(Inputs!$C$64,ISNUMBER($B7)),IF($B7=Inputs!$C$68,Inputs!$C$68,Value_Streams!$G$18*(Inputs!$C$69+Utility_Rates!$C$23)^($B7-Inputs!$C$69)),"") | E7: =IF(AND(Inputs!$C$64,ISNUMBER($B7)),IF($B7=Inputs!$C$68,Inputs!$C$68,Value_Streams!$J$18*(Inputs!$C$69+Utility_Rates!$C$22)^($B7-Inputs!$C$69)),"") | F7: =IF(AND(Inputs!$C$64,ISNUMBER($B7)),IF($B7=Inputs!$C$68,Inputs!$C$68,Value_Streams!$K$18),"") | G7: {=IF(AND(Inputs!$C$64,ISNUMBER($B7)),IF($B7=Inputs!$C$68,Inputs!$C$68,Inputs!$C$53),"")} | H7: =IF(AND(Inputs!$C$64,ISNUMBER($B7)),SUM(D7:G7),"") | I7: =IF(AND(Inputs!$C$64,ISNUMBER($B7)),IF($B7=Inputs!$C$68,Inputs!$C$68,-Inputs!$C$28*(Inputs!$C$69+Inputs!$C$29)^($B7-Inputs!$C$69)),"") | J7: {=IF(AND(Inputs!$C$64,ISNUMBER($B7)),IF(AND($B7>=Inputs!$C$69,$B7=Inputs!$C$26),-Inputs!$C$27,Inputs!$C$68),"")} | K7: =IF(AND(Inputs!$C$64,ISNUMBER($B7)),SUM(C7:F7,I7:J7),"") | L7: =IF(AND(Inputs!$C$64,ISNUMBER($B7)),SUM(K$6:K7),"") | M7: =IF(AND(Inputs!$C$64,ISNUMBER($B7)),K7+G7,"") | N7: =IF(AND(Inputs!$C$64,ISNUMBER($B7)),SUM(M$6:M7),"")
B8: =IF(ROW()-ROW($B$6)<=Inputs!$C$42,ROW()-ROW($B$6),"") | C8: {=IF(AND(Inputs!$C$64,ISNUMBER($B8)),IF($B8=Inputs!$C$68,-Inputs!$C$39,Inputs!$C$68),"")} | D8: =IF(AND(Inputs!$C$64,ISNUMBER($B8)),IF($B8=Inputs!$C$68,Inputs!$C$68,Value_Streams!$G$18*(Inputs!$C$69+Utility_Rates!$C$23)^($B8-Inputs!$C$69)),"") | E8: =IF(AND(Inputs!$C$64,ISNUMBER($B8)),IF($B8=Inputs!$C$68,Inputs!$C$68,Value_Streams!$J$18*(Inputs!$C$69+Utility_Rates!$C$22)^($B8-Inputs!$C$69)),"") | F8: =IF(AND(Inputs!$C$64,ISNUMBER($B8)),IF($B8=Inputs!$C$68,Inputs!$C$68,Value_Streams!$K$18),"") | G8: {=IF(AND(Inputs!$C$64,ISNUMBER($B8)),IF($B8=Inputs!$C$68,Inputs!$C$68,Inputs!$C$53),"")} | H8: =IF(AND(Inputs!$C$64,ISNUMBER($B8)),SUM(D8:G8),"") | I8: =IF(AND(Inputs!$C$64,ISNUMBER($B8)),IF($B8=Inputs!$C$68,Inputs!$C$68,-Inputs!$C$28*(Inputs!$C$69+Inputs!$C$29)^($B8-Inputs!$C$69)),"") | J8: {=IF(AND(Inputs!$C$64,ISNUMBER($B8)),IF(AND($B8>=Inputs!$C$69,$B8=Inputs!$C$26),-Inputs!$C$27,Inputs!$C$68),"")} | K8: =IF(AND(Inputs!$C$64,ISNUMBER($B8)),SUM(C8:F8,I8:J8),"") | L8: =IF(AND(Inputs!$C$64,ISNUMBER($B8)),SUM(K$6:K8),"") | M8: =IF(AND(Inputs!$C$64,ISNUMBER($B8)),K8+G8,"") | N8: =IF(AND(Inputs!$C$64,ISNUMBER($B8)),SUM(M$6:M8),"")
B9: =IF(ROW()-ROW($B$6)<=Inputs!$C$42,ROW()-ROW($B$6),"") | C9: {=IF(AND(Inputs!$C$64,ISNUMBER($B9)),IF($B9=Inputs!$C$68,-Inputs!$C$39,Inputs!$C$68),"")} | D9: =IF(AND(Inputs!$C$64,ISNUMBER($B9)),IF($B9=Inputs!$C$68,Inputs!$C$68,Value_Streams!$G$18*(Inputs!$C$69+Utility_Rates!$C$23)^($B9-Inputs!$C$69)),"") | E9: =IF(AND(Inputs!$C$64,ISNUMBER($B9)),IF($B9=Inputs!$C$68,Inputs!$C$68,Value_Streams!$J$18*(Inputs!$C$69+Utility_Rates!$C$22)^($B9-Inputs!$C$69)),"") | F9: =IF(AND(Inputs!$C$64,ISNUMBER($B9)),IF($B9=Inputs!$C$68,Inputs!$C$68,Value_Streams!$K$18),"") | G9: {=IF(AND(Inputs!$C$64,ISNUMBER($B9)),IF($B9=Inputs!$C$68,Inputs!$C$68,Inputs!$C$53),"")} | H9: =IF(AND(Inputs!$C$64,ISNUMBER($B9)),SUM(D9:G9),"") | I9: =IF(AND(Inputs!$C$64,ISNUMBER($B9)),IF($B9=Inputs!$C$68,Inputs!$C$68,-Inputs!$C$28*(Inputs!$C$69+Inputs!$C$29)^($B9-Inputs!$C$69)),"") | J9: {=IF(AND(Inputs!$C$64,ISNUMBER($B9)),IF(AND($B9>=Inputs!$C$69,$B9=Inputs!$C$26),-Inputs!$C$27,Inputs!$C$68),"")} | K9: =IF(AND(Inputs!$C$64,ISNUMBER($B9)),SUM(C9:F9,I9:J9),"") | L9: =IF(AND(Inputs!$C$64,ISNUMBER($B9)),SUM(K$6:K9),"") | M9: =IF(AND(Inputs!$C$64,ISNUMBER($B9)),K9+G9,"") | N9: =IF(AND(Inputs!$C$64,ISNUMBER($B9)),SUM(M$6:M9),"")
B10: =IF(ROW()-ROW($B$6)<=Inputs!$C$42,ROW()-ROW($B$6),"") | C10: {=IF(AND(Inputs!$C$64,ISNUMBER($B10)),IF($B10=Inputs!$C$68,-Inputs!$C$39,Inputs!$C$68),"")} | D10: =IF(AND(Inputs!$C$64,ISNUMBER($B10)),IF($B10=Inputs!$C$68,Inputs!$C$68,Value_Streams!$G$18*(Inputs!$C$69+Utility_Rates!$C$23)^($B10-Inputs!$C$69)),"") | E10: =IF(AND(Inputs!$C$64,ISNUMBER($B10)),IF($B10=Inputs!$C$68,Inputs!$C$68,Value_Streams!$J$18*(Inputs!$C$69+Utility_Rates!$C$22)^($B10-Inputs!$C$69)),"") | F10: =IF(AND(Inputs!$C$64,ISNUMBER($B10)),IF($B10=Inputs!$C$68,Inputs!$C$68,Value_Streams!$K$18),"") | G10: {=IF(AND(Inputs!$C$64,ISNUMBER($B10)),IF($B10=Inputs!$C$68,Inputs!$C$68,Inputs!$C$53),"")} | H10: =IF(AND(Inputs!$C$64,ISNUMBER($B10)),SUM(D10:G10),"") | I10: =IF(AND(Inputs!$C$64,ISNUMBER($B10)),IF($B10=Inputs!$C$68,Inputs!$C$68,-Inputs!$C$28*(Inputs!$C$69+Inputs!$C$29)^($B10-Inputs!$C$69)),"") | J10: {=IF(AND(Inputs!$C$64,ISNUMBER($B10)),IF(AND($B10>=Inputs!$C$69,$B10=Inputs!$C$26),-Inputs!$C$27,Inputs!$C$68),"")} | K10: =IF(AND(Inputs!$C$64,ISNUMBER($B10)),SUM(C10:F10,I10:J10),"") | L10: =IF(AND(Inputs!$C$64,ISNUMBER($B10)),SUM(K$6:K10),"") | M10: =IF(AND(Inputs!$C$64,ISNUMBER($B10)),K10+G10,"") | N10: =IF(AND(Inputs!$C$64,ISNUMBER($B10)),SUM(M$6:M10),"")
B11: =IF(ROW()-ROW($B$6)<=Inputs!$C$42,ROW()-ROW($B$6),"") | C11: {=IF(AND(Inputs!$C$64,ISNUMBER($B11)),IF($B11=Inputs!$C$68,-Inputs!$C$39,Inputs!$C$68),"")} | D11: =IF(AND(Inputs!$C$64,ISNUMBER($B11)),IF($B11=Inputs!$C$68,Inputs!$C$68,Value_Streams!$G$18*(Inputs!$C$69+Utility_Rates!$C$23)^($B11-Inputs!$C$69)),"") | E11: =IF(AND(Inputs!$C$64,ISNUMBER($B11)),IF($B11=Inputs!$C$68,Inputs!$C$68,Value_Streams!$J$18*(Inputs!$C$69+Utility_Rates!$C$22)^($B11-Inputs!$C$69)),"") | F11: =IF(AND(Inputs!$C$64,ISNUMBER($B11)),IF($B11=Inputs!$C$68,Inputs!$C$68,Value_Streams!$K$18),"") | G11: {=IF(AND(Inputs!$C$64,ISNUMBER($B11)),IF($B11=Inputs!$C$68,Inputs!$C$68,Inputs!$C$53),"")} | H11: =IF(AND(Inputs!$C$64,ISNUMBER($B11)),SUM(D11:G11),"") | I11: =IF(AND(Inputs!$C$64,ISNUMBER($B11)),IF($B11=Inputs!$C$68,Inputs!$C$68,-Inputs!$C$28*(Inputs!$C$69+Inputs!$C$29)^($B11-Inputs!$C$69)),"") | J11: {=IF(AND(Inputs!$C$64,ISNUMBER($B11)),IF(AND($B11>=Inputs!$C$69,$B11=Inputs!$C$26),-Inputs!$C$27,Inputs!$C$68),"")} | K11: =IF(AND(Inputs!$C$64,ISNUMBER($B11)),SUM(C11:F11,I11:J11),"") | L11: =IF(AND(Inputs!$C$64,ISNUMBER($B11)),SUM(K$6:K11),"") | M11: =IF(AND(Inputs!$C$64,ISNUMBER($B11)),K11+G11,"") | N11: =IF(AND(Inputs!$C$64,ISNUMBER($B11)),SUM(M$6:M11),"")
B12: =IF(ROW()-ROW($B$6)<=Inputs!$C$42,ROW()-ROW($B$6),"") | C12: {=IF(AND(Inputs!$C$64,ISNUMBER($B12)),IF($B12=Inputs!$C$68,-Inputs!$C$39,Inputs!$C$68),"")} | D12: =IF(AND(Inputs!$C$64,ISNUMBER($B12)),IF($B12=Inputs!$C$68,Inputs!$C$68,Value_Streams!$G$18*(Inputs!$C$69+Utility_Rates!$C$23)^($B12-Inputs!$C$69)),"") | E12: =IF(AND(Inputs!$C$64,ISNUMBER($B12)),IF($B12=Inputs!$C$68,Inputs!$C$68,Value_Streams!$J$18*(Inputs!$C$69+Utility_Rates!$C$22)^($B12-Inputs!$C$69)),"") | F12: =IF(AND(Inputs!$C$64,ISNUMBER($B12)),IF($B12=Inputs!$C$68,Inputs!$C$68,Value_Streams!$K$18),"") | G12: {=IF(AND(Inputs!$C$64,ISNUMBER($B12)),IF($B12=Inputs!$C$68,Inputs!$C$68,Inputs!$C$53),"")} | H12: =IF(AND(Inputs!$C$64,ISNUMBER($B12)),SUM(D12:G12),"") | I12: =IF(AND(Inputs!$C$64,ISNUMBER($B12)),IF($B12=Inputs!$C$68,Inputs!$C$68,-Inputs!$C$28*(Inputs!$C$69+Inputs!$C$29)^($B12-Inputs!$C$69)),"") | J12: {=IF(AND(Inputs!$C$64,ISNUMBER($B12)),IF(AND($B12>=Inputs!$C$69,$B12=Inputs!$C$26),-Inputs!$C$27,Inputs!$C$68),"")} | K12: =IF(AND(Inputs!$C$64,ISNUMBER($B12)),SUM(C12:F12,I12:J12),"") | L12: =IF(AND(Inputs!$C$64,ISNUMBER($B12)),SUM(K$6:K12),"") | M12: =IF(AND(Inputs!$C$64,ISNUMBER($B12)),K12+G12,"") | N12: =IF(AND(Inputs!$C$64,ISNUMBER($B12)),SUM(M$6:M12),"")
B13: =IF(ROW()-ROW($B$6)<=Inputs!$C$42,ROW()-ROW($B$6),"") | C13: {=IF(AND(Inputs!$C$64,ISNUMBER($B13)),IF($B13=Inputs!$C$68,-Inputs!$C$39,Inputs!$C$68),"")} | D13: =IF(AND(Inputs!$C$64,ISNUMBER($B13)),IF($B13=Inputs!$C$68,Inputs!$C$68,Value_Streams!$G$18*(Inputs!$C$69+Utility_Rates!$C$23)^($B13-Inputs!$C$69)),"") | E13: =IF(AND(Inputs!$C$64,ISNUMBER($B13)),IF($B13=Inputs!$C$68,Inputs!$C$68,Value_Streams!$J$18*(Inputs!$C$69+Utility_Rates!$C$22)^($B13-Inputs!$C$69)),"") | F13: =IF(AND(Inputs!$C$64,ISNUMBER($B13)),IF($B13=Inputs!$C$68,Inputs!$C$68,Value_Streams!$K$18),"") | G13: {=IF(AND(Inputs!$C$64,ISNUMBER($B13)),IF($B13=Inputs!$C$68,Inputs!$C$68,Inputs!$C$53),"")} | H13: =IF(AND(Inputs!$C$64,ISNUMBER($B13)),SUM(D13:G13),"") | I13: =IF(AND(Inputs!$C$64,ISNUMBER($B13)),IF($B13=Inputs!$C$68,Inputs!$C$68,-Inputs!$C$28*(Inputs!$C$69+Inputs!$C$29)^($B13-Inputs!$C$69)),"") | J13: {=IF(AND(Inputs!$C$64,ISNUMBER($B13)),IF(AND($B13>=Inputs!$C$69,$B13=Inputs!$C$26),-Inputs!$C$27,Inputs!$C$68),"")} | K13: =IF(AND(Inputs!$C$64,ISNUMBER($B13)),SUM(C13:F13,I13:J13),"") | L13: =IF(AND(Inputs!$C$64,ISNUMBER($B13)),SUM(K$6:K13),"") | M13: =IF(AND(Inputs!$C$64,ISNUMBER($B13)),K13+G13,"") | N13: =IF(AND(Inputs!$C$64,ISNUMBER($B13)),SUM(M$6:M13),"")
B14: =IF(ROW()-ROW($B$6)<=Inputs!$C$42,ROW()-ROW($B$6),"") | C14: {=IF(AND(Inputs!$C$64,ISNUMBER($B14)),IF($B14=Inputs!$C$68,-Inputs!$C$39,Inputs!$C$68),"")} | D14: =IF(AND(Inputs!$C$64,ISNUMBER($B14)),IF($B14=Inputs!$C$68,Inputs!$C$68,Value_Streams!$G$18*(Inputs!$C$69+Utility_Rates!$C$23)^($B14-Inputs!$C$69)),"") | E14: =IF(AND(Inputs!$C$64,ISNUMBER($B14)),IF($B14=Inputs!$C$68,Inputs!$C$68,Value_Streams!$J$18*(Inputs!$C$69+Utility_Rates!$C$22)^($B14-Inputs!$C$69)),"") | F14: =IF(AND(Inputs!$C$64,ISNUMBER($B14)),IF($B14=Inputs!$C$68,Inputs!$C$68,Value_Streams!$K$18),"") | G14: {=IF(AND(Inputs!$C$64,ISNUMBER($B14)),IF($B14=Inputs!$C$68,Inputs!$C$68,Inputs!$C$53),"")} | H14: =IF(AND(Inputs!$C$64,ISNUMBER($B14)),SUM(D14:G14),"") | I14: =IF(AND(Inputs!$C$64,ISNUMBER($B14)),IF($B14=Inputs!$C$68,Inputs!$C$68,-Inputs!$C$28*(Inputs!$C$69+Inputs!$C$29)^($B14-Inputs!$C$69)),"") | J14: {=IF(AND(Inputs!$C$64,ISNUMBER($B14)),IF(AND($B14>=Inputs!$C$69,$B14=Inputs!$C$26),-Inputs!$C$27,Inputs!$C$68),"")} | K14: =IF(AND(Inputs!$C$64,ISNUMBER($B14)),SUM(C14:F14,I14:J14),"") | L14: =IF(AND(Inputs!$C$64,ISNUMBER($B14)),SUM(K$6:K14),"") | M14: =IF(AND(Inputs!$C$64,ISNUMBER($B14)),K14+G14,"") | N14: =IF(AND(Inputs!$C$64,ISNUMBER($B14)),SUM(M$6:M14),"")
B15: =IF(ROW()-ROW($B$6)<=Inputs!$C$42,ROW()-ROW($B$6),"") | C15: {=IF(AND(Inputs!$C$64,ISNUMBER($B15)),IF($B15=Inputs!$C$68,-Inputs!$C$39,Inputs!$C$68),"")} | D15: =IF(AND(Inputs!$C$64,ISNUMBER($B15)),IF($B15=Inputs!$C$68,Inputs!$C$68,Value_Streams!$G$18*(Inputs!$C$69+Utility_Rates!$C$23)^($B15-Inputs!$C$69)),"") | E15: =IF(AND(Inputs!$C$64,ISNUMBER($B15)),IF($B15=Inputs!$C$68,Inputs!$C$68,Value_Streams!$J$18*(Inputs!$C$69+Utility_Rates!$C$22)^($B15-Inputs!$C$69)),"") | F15: =IF(AND(Inputs!$C$64,ISNUMBER($B15)),IF($B15=Inputs!$C$68,Inputs!$C$68,Value_Streams!$K$18),"") | G15: {=IF(AND(Inputs!$C$64,ISNUMBER($B15)),IF($B15=Inputs!$C$68,Inputs!$C$68,Inputs!$C$53),"")} | H15: =IF(AND(Inputs!$C$64,ISNUMBER($B15)),SUM(D15:G15),"") | I15: =IF(AND(Inputs!$C$64,ISNUMBER($B15)),IF($B15=Inputs!$C$68,Inputs!$C$68,-Inputs!$C$28*(Inputs!$C$69+Inputs!$C$29)^($B15-Inputs!$C$69)),"") | J15: {=IF(AND(Inputs!$C$64,ISNUMBER($B15)),IF(AND($B15>=Inputs!$C$69,$B15=Inputs!$C$26),-Inputs!$C$27,Inputs!$C$68),"")} | K15: =IF(AND(Inputs!$C$64,ISNUMBER($B15)),SUM(C15:F15,I15:J15),"") | L15: =IF(AND(Inputs!$C$64,ISNUMBER($B15)),SUM(K$6:K15),"") | M15: =IF(AND(Inputs!$C$64,ISNUMBER($B15)),K15+G15,"") | N15: =IF(AND(Inputs!$C$64,ISNUMBER($B15)),SUM(M$6:M15),"")
B16: =IF(ROW()-ROW($B$6)<=Inputs!$C$42,ROW()-ROW($B$6),"") | C16: {=IF(AND(Inputs!$C$64,ISNUMBER($B16)),IF($B16=Inputs!$C$68,-Inputs!$C$39,Inputs!$C$68),"")} | D16: =IF(AND(Inputs!$C$64,ISNUMBER($B16)),IF($B16=Inputs!$C$68,Inputs!$C$68,Value_Streams!$G$18*(Inputs!$C$69+Utility_Rates!$C$23)^($B16-Inputs!$C$69)),"") | E16: =IF(AND(Inputs!$C$64,ISNUMBER($B16)),IF($B16=Inputs!$C$68,Inputs!$C$68,Value_Streams!$J$18*(Inputs!$C$69+Utility_Rates!$C$22)^($B16-Inputs!$C$69)),"") | F16: =IF(AND(Inputs!$C$64,ISNUMBER($B16)),IF($B16=Inputs!$C$68,Inputs!$C$68,Value_Streams!$K$18),"") | G16: {=IF(AND(Inputs!$C$64,ISNUMBER($B16)),IF($B16=Inputs!$C$68,Inputs!$C$68,Inputs!$C$53),"")} | H16: =IF(AND(Inputs!$C$64,ISNUMBER($B16)),SUM(D16:G16),"") | I16: =IF(AND(Inputs!$C$64,ISNUMBER($B16)),IF($B16=Inputs!$C$68,Inputs!$C$68,-Inputs!$C$28*(Inputs!$C$69+Inputs!$C$29)^($B16-Inputs!$C$69)),"") | J16: {=IF(AND(Inputs!$C$64,ISNUMBER($B16)),IF(AND($B16>=Inputs!$C$69,$B16=Inputs!$C$26),-Inputs!$C$27,Inputs!$C$68),"")} | K16: =IF(AND(Inputs!$C$64,ISNUMBER($B16)),SUM(C16:F16,I16:J16),"") | L16: =IF(AND(Inputs!$C$64,ISNUMBER($B16)),SUM(K$6:K16),"") | M16: =IF(AND(Inputs!$C$64,ISNUMBER($B16)),K16+G16,"") | N16: =IF(AND(Inputs!$C$64,ISNUMBER($B16)),SUM(M$6:M16),"")
B17: =IF(ROW()-ROW($B$6)<=Inputs!$C$42,ROW()-ROW($B$6),"") | C17: {=IF(AND(Inputs!$C$64,ISNUMBER($B17)),IF($B17=Inputs!$C$68,-Inputs!$C$39,Inputs!$C$68),"")} | D17: =IF(AND(Inputs!$C$64,ISNUMBER($B17)),IF($B17=Inputs!$C$68,Inputs!$C$68,Value_Streams!$G$18*(Inputs!$C$69+Utility_Rates!$C$23)^($B17-Inputs!$C$69)),"") | E17: =IF(AND(Inputs!$C$64,ISNUMBER($B17)),IF($B17=Inputs!$C$68,Inputs!$C$68,Value_Streams!$J$18*(Inputs!$C$69+Utility_Rates!$C$22)^($B17-Inputs!$C$69)),"") | F17: =IF(AND(Inputs!$C$64,ISNUMBER($B17)),IF($B17=Inputs!$C$68,Inputs!$C$68,Value_Streams!$K$18),"") | G17: {=IF(AND(Inputs!$C$64,ISNUMBER($B17)),IF($B17=Inputs!$C$68,Inputs!$C$68,Inputs!$C$53),"")} | H17: =IF(AND(Inputs!$C$64,ISNUMBER($B17)),SUM(D17:G17),"") | I17: =IF(AND(Inputs!$C$64,ISNUMBER($B17)),IF($B17=Inputs!$C$68,Inputs!$C$68,-Inputs!$C$28*(Inputs!$C$69+Inputs!$C$29)^($B17-Inputs!$C$69)),"") | J17: {=IF(AND(Inputs!$C$64,ISNUMBER($B17)),IF(AND($B17>=Inputs!$C$69,$B17=Inputs!$C$26),-Inputs!$C$27,Inputs!$C$68),"")} | K17: =IF(AND(Inputs!$C$64,ISNUMBER($B17)),SUM(C17:F17,I17:J17),"") | L17: =IF(AND(Inputs!$C$64,ISNUMBER($B17)),SUM(K$6:K17),"") | M17: =IF(AND(Inputs!$C$64,ISNUMBER($B17)),K17+G17,"") | N17: =IF(AND(Inputs!$C$64,ISNUMBER($B17)),SUM(M$6:M17),"")
B18: =IF(ROW()-ROW($B$6)<=Inputs!$C$42,ROW()-ROW($B$6),"") | C18: {=IF(AND(Inputs!$C$64,ISNUMBER($B18)),IF($B18=Inputs!$C$68,-Inputs!$C$39,Inputs!$C$68),"")} | D18: =IF(AND(Inputs!$C$64,ISNUMBER($B18)),IF($B18=Inputs!$C$68,Inputs!$C$68,Value_Streams!$G$18*(Inputs!$C$69+Utility_Rates!$C$23)^($B18-Inputs!$C$69)),"") | E18: =IF(AND(Inputs!$C$64,ISNUMBER($B18)),IF($B18=Inputs!$C$68,Inputs!$C$68,Value_Streams!$J$18*(Inputs!$C$69+Utility_Rates!$C$22)^($B18-Inputs!$C$69)),"") | F18: =IF(AND(Inputs!$C$64,ISNUMBER($B18)),IF($B18=Inputs!$C$68,Inputs!$C$68,Value_Streams!$K$18),"") | G18: {=IF(AND(Inputs!$C$64,ISNUMBER($B18)),IF($B18=Inputs!$C$68,Inputs!$C$68,Inputs!$C$53),"")} | H18: =IF(AND(Inputs!$C$64,ISNUMBER($B18)),SUM(D18:G18),"") | I18: =IF(AND(Inputs!$C$64,ISNUMBER($B18)),IF($B18=Inputs!$C$68,Inputs!$C$68,-Inputs!$C$28*(Inputs!$C$69+Inputs!$C$29)^($B18-Inputs!$C$69)),"") | J18: {=IF(AND(Inputs!$C$64,ISNUMBER($B18)),IF(AND($B18>=Inputs!$C$69,$B18=Inputs!$C$26),-Inputs!$C$27,Inputs!$C$68),"")} | K18: =IF(AND(Inputs!$C$64,ISNUMBER($B18)),SUM(C18:F18,I18:J18),"") | L18: =IF(AND(Inputs!$C$64,ISNUMBER($B18)),SUM(K$6:K18),"") | M18: =IF(AND(Inputs!$C$64,ISNUMBER($B18)),K18+G18,"") | N18: =IF(AND(Inputs!$C$64,ISNUMBER($B18)),SUM(M$6:M18),"")
... B31: =IF(ROW()-ROW($B$6)<=Inputs!$C$42,ROW()-ROW($B$6),"") | C31: {=IF(AND(Inputs!$C$64,ISNUMBER($B31)),IF($B31=Inputs!$C$68,-Inputs!$C$39,Inputs!$C$68),"")} | D31: =IF(AND(Inputs!$C$64,ISNUMBER($B31)),IF($B31=Inputs!$C$68,Inputs!$C$68,Value_Streams!$G$18*(Inputs!$C$69+Utility_Rates!$C$23)^($B31-Inputs!$C$69)),"") | E31: =IF(AND(Inputs!$C$64,ISNUMBER($B31)),IF($B31=Inputs!$C$68,Inputs!$C$68,Value_Streams!$J$18*(Inputs!$C$69+Utility_Rates!$C$22)^($B31-Inputs!$C$69)),"") | F31: =IF(AND(Inputs!$C$64,ISNUMBER($B31)),IF($B31=Inputs!$C$68,Inputs!$C$68,Value_Streams!$K$18),"") | G31: {=IF(AND(Inputs!$C$64,ISNUMBER($B31)),IF($B31=Inputs!$C$68,Inputs!$C$68,Inputs!$C$53),"")} | H31: =IF(AND(Inputs!$C$64,ISNUMBER($B31)),SUM(D31:G31),"") | I31: =IF(AND(Inputs!$C$64,ISNUMBER($B31)),IF($B31=Inputs!$C$68,Inputs!$C$68,-Inputs!$C$28*(Inputs!$C$69+Inputs!$C$29)^($B31-Inputs!$C$69)),"") | J31: {=IF(AND(Inputs!$C$64,ISNUMBER($B31)),IF(AND($B31>=Inputs!$C$69,$B31=Inputs!$C$26),-Inputs!$C$27,Inputs!$C$68),"")} | K31: =IF(AND(Inputs!$C$64,ISNUMBER($B31)),SUM(C31:F31,I31:J31),"") | L31: =IF(AND(Inputs!$C$64,ISNUMBER($B31)),SUM(K$6:K31),"") | M31: =IF(AND(Inputs!$C$64,ISNUMBER($B31)),K31+G31,"") | N31: =IF(AND(Inputs!$C$64,ISNUMBER($B31)),SUM(M$6:M31),"")
B34: RETURNS | C34: Excl. resiliency | D34: Incl. resiliency
B35: Project IRR | C35: =IF(Inputs!$C$64,IFERROR(IRR($K$6:INDEX($K$6:$K$31,Inputs!$C$42+Inputs!$C$69)),"N/M"),"") | D35: =IF(Inputs!$C$64,IFERROR(IRR($M$6:INDEX($M$6:$M$31,Inputs!$C$42+Inputs!$C$69)),"N/M"),"")
B36: Project NPV | C36: =IF(Inputs!$C$64,NPV(Inputs!$C$43,$K$7:INDEX($K$6:$K$31,Inputs!$C$42+Inputs!$C$69))+$K$6,"") | D36: =IF(Inputs!$C$64,NPV(Inputs!$C$43,$M$7:INDEX($M$6:$M$31,Inputs!$C$42+Inputs!$C$69))+$M$6,"")
B37: Simple payback (years) | C37: =IF(Inputs!$C$64,IF(SUM(D7:F7,I7)>Inputs!$C$68,Inputs!$C$39/(SUM(D7:F7,I7)),"Not achieved"),"") | D37: =IF(Inputs!$C$64,IF(SUM(D7:F7,I7)+G7>Inputs!$C$68,Inputs!$C$39/(SUM(D7:F7,I7)+G7),"Not achieved"),"")
B38: Lifetime net benefit | C38: =IF(Inputs!$C$64,SUM($K$6:INDEX($K$6:$K$31,Inputs!$C$42+Inputs!$C$69)),"") | D38: =IF(Inputs!$C$64,SUM($M$6:INDEX($M$6:$M$31,Inputs!$C$42+Inputs!$C$69)),"")
B41: Future-year physical savings and dispatch are held constant. Only demand / energy prices and O&M escalate.
B42: Degradation and useful life are reference assumptions, not dispatch adjustments. Replacement is a one-time nominal outflow.
B43: Simple payback = installed cost ÷ Year 1 recurring net benefit; excludes escalation, replacement, and discounting.
B44: Lifetime net benefit is the undiscounted sum of selected-horizon net cash flows, including Year 0. N/M = IRR not meaningful.
B45: Program revenue is held at its Year 1 value (program rates are set by the tariff and are not escalated).

Sheet Outputs
B2: MULTIFAMILY BESS | OWNER SUMMARY
B3: {=Inputs!C65}
B5: Metric | C5: Excl. resiliency | D5: Incl. resiliency
B6: Battery power (kW) | C6: {=IF(ISNUMBER(Inputs!C16),Inputs!C16,"")} | D6: {=IF(ISNUMBER(C6),C6,"")}
B7: Nameplate capacity (kWh) | C7: {=IF(ISNUMBER(Inputs!C17),Inputs!C17,"")} | D7: {=IF(ISNUMBER(C7),C7,"")}
B8: Total installed cost ($) | C8: {=IF(ISNUMBER(Inputs!C39),Inputs!C39,"")} | D8: {=IF(ISNUMBER(C8),C8,"")}
B10: Year 1 demand savings ($) | C10: {=IF(ISNUMBER(Value_Streams!G18),Value_Streams!G18,"")} | D10: {=IF(ISNUMBER(C10),C10,"")}
B11: Year 1 arbitrage savings ($) | C11: {=IF(ISNUMBER(Value_Streams!J18),Value_Streams!J18,"")} | D11: {=IF(ISNUMBER(C11),C11,"")}
B12: Year 1 program revenue ($) | C12: =IF(ISNUMBER(Value_Streams!K18),Value_Streams!K18,"") | D12: =IF(ISNUMBER(C12),C12,"")
B13: Year 1 resiliency value ($) | C13: {=Inputs!$C$68} | D13: {=IF(ISNUMBER(Inputs!C53),Inputs!C53,"")}
B14: Total Year 1 benefit ($) | C14: =IF(AND(Inputs!C62,ISNUMBER(C13)),SUM(C10:C13),"") | D14: =IF(AND(Inputs!C62,ISNUMBER(D13)),SUM(D10:D13),"")
B15: Year 1 O&M expense ($) | C15: =IF(ISNUMBER(Inputs!C28),-Inputs!C28,"") | D15: =IF(ISNUMBER(Inputs!C28),-Inputs!C28,"")
B16: Year 1 recurring net benefit ($) | C16: =IF(AND(ISNUMBER(C14),ISNUMBER(C15)),SUM(C14:C15),"") | D16: =IF(AND(ISNUMBER(D14),ISNUMBER(D15)),SUM(D14:D15),"")
B18: Project IRR (%) | C18: {=IF(Inputs!C64,Project_Cash_Flow!C35,"")} | D18: {=IF(Inputs!C64,Project_Cash_Flow!D35,"")}
B19: Project NPV ($) | C19: {=IF(Inputs!C64,Project_Cash_Flow!C36,"")} | D19: {=IF(Inputs!C64,Project_Cash_Flow!D36,"")}
B20: Simple payback (years) | C20: {=IF(Inputs!C64,Project_Cash_Flow!C37,"")} | D20: {=IF(Inputs!C64,Project_Cash_Flow!D37,"")}
B21: Lifetime net benefit ($) | C21: {=IF(Inputs!C64,Project_Cash_Flow!C38,"")} | D21: {=IF(Inputs!C64,Project_Cash_Flow!D38,"")}
B24: START HERE
B25: 1. Enter project assumptions in Inputs; enter rates and edit the TOU schedule in Utility_Rates.
B26: 2. Paste 8,760 numeric values into each blue hourly column. Use explicit zeros; do not include headers.
B27: 3. Review monthly savings and bill reconciliation, then compare returns above. Draft horizon: 1–25 years.
B29: MODEL BOUNDARIES
B30: Resiliency is assumed economic value, not necessarily bill savings or owner cash receipts.
B31: Imported dispatch includes charging and efficiency losses. No exports, optimizer, or SOC / cycle validation.
B32: Year 1 physical savings stay constant; no degradation simulation. Align the horizon with useful life.
B33: Rates and costs are blank; 2027 start, 25 years, 8% discount rate, zero O&M / escalation / resiliency are draft defaults.
